Workbook

Sheet BUTTS
A1: Serial Number | B1: Logger Name | C1: Bat_ID | D1: Bat Pittag | E1: Injection_Used | F1: Calibration | G1: Group | H1: Date Attached | I1: Date Removed | J1: BUTT Status | K1: Treatment | L1: Innoculation Date | M1: Boost Date | N1: Trim Date | O1: Logger location | P1: Notes
A2: BB00000081230841 | B2: A1 | C2: 3 | D2: IE36076 | E2: Boost | F2: 2 | G2: 1 | H2: 45811 | I2: 45819 | J2: Downloaded | K2: eVLP alone | L2: 45792 | M2: 45813 | N2: =I2-1 -> 45818 | P2: Found dead 11-Jun
A3: B300000081225D41 | B3: A2 | C3: 9 | D3: IE36014 | E3: Boost | F3: 2 | G3: 1 | H3: 45811 | I3: 45821 | J3: Downloaded | K3: eVLP+cGAMP | L3: 45792 | M3: 45813 | N3: =I3-1 -> 45820
A4: 7F000000818B3741 | B4: A3 | C4: 16 | D4: IE36102 | E4: Boost | F4: 2 | G4: 1 | H4: 45811 | I4: 45821 | J4: Downloaded | K4: SHAM | L4: 45792 | M4: 45813 | N4: =I4-1 -> 45820
A5: D8000000818C4541 | B5: A4 | C5: 21 | D5: IE36042 | E5: Boost | F5: 2 | G5: 1 | H5: 45811 | I5: 45821 | J5: Downloaded | K5: eVLP+cGAMP | L5: 45792 | M5: 45813 | N5: =I5-1 -> 45820 | P5: I think the logger fell off on 9-Jun
A6: FF00000081816941 | B6: A5 | C6: 22 | D6: IE36082 | E6: Boost | F6: 2 | G6: 1 | H6: 45811 | I6: 45821 | J6: Downloaded | K6: eVLP+LPS | L6: 45792 | M6: 45813 | N6: =I6-1 -> 45820
A7: 63000000811C2F41 | B7: A6 | C7: 26 | D7: IE36030 | E7: Boost | F7: 2 | G7: 1 | H7: 45811 | I7: 45821 | J7: Downloaded | K7: eVLP+LPS | L7: 45792 | M7: 45813 | N7: =I7-1 -> 45820
A8: 2F0000008116ED41 | B8: A7 | C8: 28 | D8: IE36074 | E8: Boost | F8: 2 | G8: 1 | H8: 45811 | J8: No data | K8: eVLP+POLY I:C | L8: 45792 | M8: 45813
A9: 0700000081190F41 | B9: B2 | C9: 39 | D9: IE36044 | E9: Boost | F9: 2 | G9: 2 | H9: 45813 | I9: 45821 | J9: Downloaded | K9: eVLP+POLY I:C | L9: 45794 | M9: 45815 | N9: =I9-1 -> 45820 | P9: Logger reattached 7-Jun
A10: 770000008187D741 | B10: B3 | C10: 40 | D10: IE36023 | E10: Boost | F10: 2 | G10: 2 | H10: 45813 | I10: 45818 | J10: No data | K10: eVLP+LPS | L10: 45794 | M10: 45815 | N10: =I10-1 -> 45817 | P10: Logger fell off - reattached
A11: E500000081218941 | B11: B7 | C11: 41 | D11: IE36058 | E11: Boost | F11: 2 | G11: 2 | H11: 45813 | I11: 45821 | J11: Downloaded | K11: SHAM | L11: 45794 | M11: 45815 | N11: =I11-1 -> 45820
A12: 76000000811A4241 | B12: B9 | C12: 44 | D12: IE36088 | E12: Boost | F12: 2 | G12: 2 | H12: 45813 | I12: 45821 | J12: Downloaded | K12: eVLP+POLY I:C | L12: 45794 | M12: 45815 | N12: =I12-1 -> 45820
A13: 7D0000008122D241 | B13: B4 | C13: 46 | D13: IE360005 | E13: Boost | F13: 2 | G13: 2 | H13: 45813 | I13: 45821 | J13: Downloaded | K13: eVLP alone | L13: 45794 | M13: 45815 | N13: =I13-1 -> 45820 | P13: More glue added on 6-Jun
A14: 2300000081816D41 | B14: B10 | C14: 47 | D14: IE36060 | E14: Boost | F14: 2 | G14: 2 | H14: 45813 | I14: 45821 | J14: Downloaded | K14: SHAM | L14: 45794 | M14: 45815 | N14: =I14-1 -> 45820 | O14: Butt | P14: Logger fell off - reattached on butt on 6-Jun
A15: CD00000081881A41 | B15: B15 | C15: 48 | D15: IE36051 | E15: Boost | F15: 2 | G15: 2 | H15: 45814 | I15: 45821 | J15: Downloaded | K15: eVLP+LPS | L15: 45794 | M15: 45815 | N15: =I15-1 -> 45820 | P15: Logger falling off and reattached 7-Jun
A16: 1C000000811B7F41 | B16: A8 | C16: 49 | D16: IE36009 | E16: Boost | F16: 2 | G16: 1 | H16: 45811 | I16: 45821 | J16: Downloaded | K16: SHAM | L16: 45792 | M16: 45813 | N16: =I16-1 -> 45820
A17: 46000000811E9741 | B17: B11 | C17: 50 | D17: IE36071 | E17: Boost | F17: 2 | G17: 2 | H17: 45813 | I17: 45821 | J17: Downloaded | K17: eVLP alone | L17: 45794 | M17: 45815 | N17: =I17-1 -> 45820 | P17: Logger fell off - reattached maybe on 6-Jun
A18: D3000000811C3A41 | B18: B1 | C18: 52 | D18: IE36105 | E18: Boost | F18: 2 | G18: 2 | H18: 45813 | I18: 45821 | J18: No data | K18: eVLP alone | L18: 45794 | M18: 45815 | N18: =I18-1 -> 45820
A19: A7000000811AA941 | B19: B6 | C19: 53 | D19: IE36049 | E19: Boost | F19: 2 | G19: 2 | H19: 45813 | I19: 45813 | J19: No data | K19: eVLP alone | L19: 45794 | M19: NA | P19: Fell off and not reattached
A20: 200000081173241 | B20: B5 | C20: 54 | D20: IE36056 | E20: Boost | F20: 2 | G20: 2 | H20: 45813 | I20: 45821 | J20: Downloaded | K20: eVLP+cGAMP | L20: 45794 | M20: 45815 | N20: =I20-1 -> 45820 | O20: Butt | P20: Logger fell off - reattached on butt on 6-Jun
A21: DF00000081814041 | B21: B12 | C21: 55 | D21: IE36045 | E21: Boost | F21: 2 | G21: 2 | H21: 45814 | I21: 45821 | J21: Downloaded | K21: eVLP+POLY I:C | L21: 45794 | M21: 45815 | N21: =I21-1 -> 45820 | P21: Logger fell off - reattached
A22: B40000008187B741 | B22: B14 | C22: 56 | D22: IE36013 | E22: Boost | F22: 2 | G22: 2 | H22: 45813 | I22: 45821 | J22: No Data | K22: SHAM | L22: 45794 | M22: 45815 | N22: =I22-1 -> 45820
A23: 04000000811ED641 | B23: B8 | C23: 60 | D23: IE36029 | E23: Boost | F23: 2 | G23: 2 | H23: 45813 | I23: 45821 | J23: Downloaded | K23: eVLP+cGAMP | L23: 45794 | M23: 45815 | N23: =I23-1 -> 45820 | P23: Logger fell off - reattached maybe on 6-Jun
A24: 1000000081241041 | B24: B13 | C24: 62 | D24: IE36098 | E24: Boost | F24: 2 | G24: 2 | H24: 45814 | I24: 45821 | J24: Downloaded | K24: eVLP+LPS | L24: 45794 | M24: 45815 | N24: =I24-1 -> 45820 | P24: Logger fell off - reattached
A25: 2D00000081244E41 | B25: C1 | C25: 64.1 | D25: IE36054 | E25: Initial | F25: 1 | G25: 3 | H25: 45797 | I25: 45820 | J25: Downloaded | K25: TC | L25: 45803 | M25: 45824 | N25: =I25-1 -> 45819
A26: F200000081239341 | B26: B20 | C26: 64.2 | D26: IE36054 | E26: Boost | F26: 2 | G26: 3 | H26: 45822 | I26: 45826 | J26: Downloaded | K26: TC | L26: 45803 | M26: 45824 | N26: =I26-1 -> 45825 | O26: Butt | P26: Data does not look right, drops to -47
A27: 4D00000081190241 | B27: C2 | C27: 66 | D27: IE36083 | E27: Initial | F27: 1 | G27: 3 | H27: 45797 | I27: 45802 | J27: No Data | K27: Hot | L27: 45803 | M27: NA | N27: =I27-1 -> 45801 | P27: Logger half off on 21-May - reglued; Logger off on 25-May
A28: 5000000081186C41 | B28: C3 | C28: 67 | D28: IE36070 | E28: Initial | F28: 1 | G28: 3 | H28: 45797 | I28: 45812 | J28: No Data | K28: TC | L28: 45803 | M28: NA | N28: =I28-1 -> 45811 | O28: Butt | P28: Died around 4-Jun
A29: 8300000081849D41 | B29: C4 | C29: 68.1 | D29: IE36095 | E29: Initial | F29: 1 | G29: 3 | H29: 45797 | I29: 45811 | J29: Downloaded | K29: TC | L29: 45803 | M29: 45824 | N29: =I29-1 -> 45810
A30: 01000000811F6C41 | B30: A10 | C30: 68.2 | D30: IE36095 | E30: Boost | F30: 2 | G30: 3 | H30: 45822 | I30: 45826 | J30: Downloaded | K30: TC | L30: 45803 | M30: 45824 | N30: =I30-1 -> 45825 | O30: Butt | P30: Reattached on butt on 16-Jun
A31: 7D000000818B2441 | B31: C5 | C31: 69 | D31: IE36089 | E31: Initial | F31: 1 | G31: 3 | H31: 45797 | I31: 45804 | J31: No Data | K31: Hot | L31: 45803 | M31: NA | N31: =I31-1 -> 45803 | P31: Dead on 27-May
A32: 9A000000818A5241 | B32: C6 | C32: 71 | D32: IE36015 | E32: Initial | F32: 1 | G32: 3 | H32: 45797 | I32: 45805 | J32: Logger Lost | K32: Hot | L32: 45803 | M32: 45824 | N32: =I32-1 -> 45804
A33: 7E00000081224441 | B33: B16 | C33: 71.2 | D33: IE36015 | E33: Boost | F33: 2 | G33: 3 | H33: 45822 | I33: 45826 | J33: Downloaded | K33: Hot | L33: 45803 | M33: 45824 | N33: =I33-1 -> 45825 | P33: Fell off and reattached on 15-Jun
A34: B400000081858541 | B34: C7 | C34: 73 | D34: IE36075 | E34: Initial | F34: 1 | G34: 3 | H34: 45797 | I34: 45797 | J34: No Data | K34: TC | L34: 45803 | M34: 45824 | N34: =I34-1 -> 45796 | P34: Fell off and lost- attached C18 and never reattached C7
A35: 3D000000818A6F41 | B35: C18 | C35: 73.2 | D35: IE36075 | E35: Initial | F35: 1 | G35: 3 | H35: 45798 | I35: 45810 | J35: No Data | K35: TC | L35: 45803 | M35: 45824 | N35: =I35-1 -> 45809 | P35: Logger fell off 22-May
A36: E6000000811F0341 | B36: A14 | C36: 73.3 | D36: IE36075 | E36: Boost | F36: 2 | G36: 3 | H36: 45822 | I36: 45822 | J36: Downloaded | K36: TC | L36: 45803 | M36: 45824 | N36: 45823 | P36: Bat removed logger the same night it was atttached. Circuit board exposed so discarded logger and attached new B19
A37: 6100000081222041 | B37: B19 | C37: 73.4 | D37: IE36075 | E37: Boost | F37: 2 | G37: 3 | H37: 45823 | I37: 45826 | J37: Downloaded | K37: TC | L37: 45803 | M37: 45824 | N37: =I37-1 -> 45825 | O37: Butt | P37: Reattached on butt on 16-Jun
C38: 73.9 | D38: IE36075 | E38: Boost | F38: 2 | G38: 3 | H38: 45822 | I38: 45826 | J38: Downloaded | K38: TC | L38: 45803 | M38: 45824 | N38: =I38-1 -> 45825 | P38: Created row for combined data
A39: 53000000811AC841 | B39: C8 | C39: 74.1 | D39: IE36053 | E39: Initial | F39: 1 | G39: 3 | H39: 45797 | I39: 45810 | J39: Downloaded | K39: TC | L39: 45803 | M39: 45824 | N39: =I39-1 -> 45809
A40: AC00000081223941 | B40: A9 | C40: 74.2 | D40: IE36053 | E40: Boost | F40: 2 | G40: 3 | H40: 45822 | I40: 45826 | J40: Downloaded | K40: TC | L40: 45803 | M40: 45824 | N40: =I40-1 -> 45825 | P40: More glue added to logger on 15-Jun
...

Sheet Counts
A2: Treatments | B2: Downloaded | C2: No Data
A3: SHAM | B3: =COUNTIFS(BUTTS!K:K,"SHAM",BUTTS!J:J,"Downloaded") -> 4 | C3: =COUNTIFS(BUTTS!K:K,"SHAM",BUTTS!J:J,"No Data") -> 1
A4: eVLP | B4: =COUNTIFS(BUTTS!K:K,"eVLP",BUTTS!J:J,"Downloaded") -> 0 | C4: =COUNTIFS(BUTTS!K:K,"eVLP",BUTTS!J:J,"No Data") -> 0
A5: eVLP + POLY | B5: =COUNTIFS(BUTTS!K:K,"eVLP+POLY",BUTTS!J:J,"Downloaded") -> 0 | C5: =COUNTIFS(BUTTS!K:K,"eVLP+POLY",BUTTS!J:J,"No Data") -> 0
A6: eVLP + cGAMP | B6: =COUNTIFS(BUTTS!K:K,"eVLP+cGAMP",BUTTS!J:J,"Downloaded") -> 4 | C6: =COUNTIFS(BUTTS!K:K,"eVLP+cGAMP",BUTTS!J:J,"No Data") -> 0
A7: eVLP + LPS | B7: =COUNTIFS(BUTTS!K:K,"eVLP+LPS",BUTTS!J:J,"Downloaded") -> 4 | C7: =COUNTIFS(BUTTS!K:K,"eVLP+LPS",BUTTS!J:J,"No Data") -> 1
A8: Cold | B8: =COUNTIFS(BUTTS!K:K,"Cold",BUTTS!J:J,"Downloaded") -> 0 | C8: =COUNTIFS(BUTTS!K:K,"Cold",BUTTS!J:J,"No Data") -> 0
A9: Hot | B9: =COUNTIFS(BUTTS!K:K,"Hot",BUTTS!J:J,"Downloaded") -> 4 | C9: =COUNTIFS(BUTTS!K:K,"Hot",BUTTS!J:J,"No Data") -> 5

Sheet Roost Temps
A1: Serial Number | B1: Location | C1: Group
A2: F900000081225041 | B2: Union North | C2: 1 | E2: 45827 | F2: Downloaded
A3: 9E0000008119FA41 | B3: Union Ambient | C3: 1 | E3: 45827 | F3: Downloaded
A4: 0800000081176D41 | B4: Union East | C4: 1 | E4: 45827 | F4: Downloaded
A5: AC00000081200B41 | B5: Rivendell/Cold Top | C5: 3
A6: 16000000811C6F41 | B6: Rivendell/Cold Bottom | C6: 3
A7: EF000000811ED341 | B7: Incubator Ambient | C7: 3
A8: F300000081203D41 | B8: Mordor/Hot Top | C8: 3
A9: B5000000811F5F41 | B9: Mordor/Hot Bottom | C9: 3
A10: B5000000811F5F41 | B10: G3 Right side of right cage (south) | C10: 3 | D10: 45822 | E10: 45826 | F10: Downloaded
A11: 16000000811C6F41 | B11: G3 Left side of left cage (north) | C11: 3 | D11: 45822 | E11: 45826 | F11: Downloaded
A12: ED00000081189641 | B12: Berlin | C12: 1,2,3 | D12: 45822
