Workbook

Sheet Database Info
A1: Column 'Date Removed' is either termination date, date the bat died, or date the next logger was applied. Here just for general trimming in R

Sheet Loggers
A1: Serial Number | B1: Logger Name | C1: Bat Band | D1: Bat Pittag | E1: Treatment | F1: Group | G1: Sex | H1: Date Attached | I1: Date Removed | J1: BUTT Status | K1: Calibration | L1: Experiment D Died | M1: Logger location | N1: Notes
A2: 1C00000081866F41 | B2: A1 | C2: DMR03190 | D2: APS36067 | E2: {=IFERROR(INDEX(Metadata!M:M, MATCH(C2,Metadata!A:A, 0)),"")} -> NoCo | F2: {=IFERROR(INDEX(Metadata!N:N, MATCH(D2,Metadata!B:B, 0)),"")} -> GP 1 | G2: {=IFERROR(INDEX(Metadata!I:I, MATCH(D2,Metadata!B:B, 0)),"")} -> Male | H2: 45906 | I2: 45910 | J2: Downloaded | K2: 1 | L2: {=IFERROR(INDEX(Metadata!O:O, MATCH(C2,Metadata!A:A, 0)),"")} -> D3
A3: CB0000008183CC41 | B3: A2 | C3: DMR03152 | D3: APS36021 | E3: {=IFERROR(INDEX(Metadata!M:M, MATCH(C3,Metadata!A:A, 0)),"")} -> Primary | F3: =IFERROR(INDEX(Metadata!N:N, MATCH(C3,Metadata!A:A, 0)),"") -> GP 2 | G3: =IFERROR(INDEX(Metadata!I:I, MATCH(C3,Metadata!A:A, 0)),"") -> Male | H3: 45902 | I3: 45947 | J3: Downloaded | K3: 1 | L3: {=IFERROR(INDEX(Metadata!O:O, MATCH(C3,Metadata!A:A, 0)),"")} -> D36
A4: 7F000000818B3741 | B4: A3 | C4: DMR03191 | D4: APS36108 | E4: {=IFERROR(INDEX(Metadata!M:M, MATCH(C4,Metadata!A:A, 0)),"")} -> Dual | F4: =IFERROR(INDEX(Metadata!N:N, MATCH(C4,Metadata!A:A, 0)),"") -> GP 2 | G4: =IFERROR(INDEX(Metadata!I:I, MATCH(C4,Metadata!A:A, 0)),"") -> Male | H4: 45902 | I4: 45947 | J4: Downloaded | K4: 1 | L4: {=IFERROR(INDEX(Metadata!O:O, MATCH(C4,Metadata!A:A, 0)),"")} -> D36
A5: 53000000811AC841 | B5: A4 | C5: DMR03154 | D5: APS60123 | E5: {=IFERROR(INDEX(Metadata!M:M, MATCH(C5,Metadata!A:A, 0)),"")} -> SHAM | F5: =IFERROR(INDEX(Metadata!N:N, MATCH(C5,Metadata!A:A, 0)),"") -> GP 1 | G5: =IFERROR(INDEX(Metadata!I:I, MATCH(C5,Metadata!A:A, 0)),"") -> Male | H5: 45906 | I5: 45929 | J5: Missing | K5: 1 | L5: {=IFERROR(INDEX(Metadata!O:O, MATCH(C5,Metadata!A:A, 0)),"")} -> D36
A6: 200000081173241 | B6: A5 | C6: DMR03162 | D6: APS36106 | E6: {=IFERROR(INDEX(Metadata!M:M, MATCH(C6,Metadata!A:A, 0)),"")} -> Dual | F6: =IFERROR(INDEX(Metadata!N:N, MATCH(C6,Metadata!A:A, 0)),"") -> GP 1 | G6: =IFERROR(INDEX(Metadata!I:I, MATCH(C6,Metadata!A:A, 0)),"") -> Female | H6: 45902 | I6: 45929 | J6: Downloaded | K6: 1 | L6: {=IFERROR(INDEX(Metadata!O:O, MATCH(C6,Metadata!A:A, 0)),"")} -> D36
A7: BB00000081230841 | B7: A6 | C7: DMR03161 | D7: APS60125 | E7: {=IFERROR(INDEX(Metadata!M:M, MATCH(C7,Metadata!A:A, 0)),"")} -> Secondary | F7: =IFERROR(INDEX(Metadata!N:N, MATCH(C7,Metadata!A:A, 0)),"") -> GP 2 | G7: =IFERROR(INDEX(Metadata!I:I, MATCH(C7,Metadata!A:A, 0)),"") -> Female | H7: 45902 | I7: 45938 | J7: Downloaded | K7: 1 | L7: {=IFERROR(INDEX(Metadata!O:O, MATCH(C7,Metadata!A:A, 0)),"")} -> D27
A8: C5000000811EA541 | B8: A7 | C8: DMR03165 | D8: APS60087 | E8: {=IFERROR(INDEX(Metadata!M:M, MATCH(C8,Metadata!A:A, 0)),"")} -> NoCo | F8: =IFERROR(INDEX(Metadata!N:N, MATCH(C8,Metadata!A:A, 0)),"") -> GP 2 | G8: =IFERROR(INDEX(Metadata!I:I, MATCH(C8,Metadata!A:A, 0)),"") -> Female | H8: 45909 | I8: 45916 | J8: Downloaded | K8: 1 | L8: {=IFERROR(INDEX(Metadata!O:O, MATCH(C8,Metadata!A:A, 0)),"")} -> D5
A9: 46000000811E9741 | B9: A8 | C9: DMR03182 | D9: APS60132 | E9: {=IFERROR(INDEX(Metadata!M:M, MATCH(C9,Metadata!A:A, 0)),"")} -> Dual | F9: =IFERROR(INDEX(Metadata!N:N, MATCH(C9,Metadata!A:A, 0)),"") -> GP 1 | G9: =IFERROR(INDEX(Metadata!I:I, MATCH(C9,Metadata!A:A, 0)),"") -> Female | H9: 45902 | I9: 45944 | J9: Downloaded | K9: 1 | L9: {=IFERROR(INDEX(Metadata!O:O, MATCH(C9,Metadata!A:A, 0)),"")} -> D36
A10: 2D00000081244E41 | B10: A9 | C10: DMR03174 | D10: APS60148 | E10: {=IFERROR(INDEX(Metadata!M:M, MATCH(C10,Metadata!A:A, 0)),"")} -> NoCo | F10: =IFERROR(INDEX(Metadata!N:N, MATCH(C10,Metadata!A:A, 0)),"") -> GP 1 | G10: =IFERROR(INDEX(Metadata!I:I, MATCH(C10,Metadata!A:A, 0)),"") -> Female | H10: 45906 | I10: 45915 | J10: No Data | K10: 1 | L10: {=IFERROR(INDEX(Metadata!O:O, MATCH(C10,Metadata!A:A, 0)),"")} -> D6
A11: DF00000081814041 | B11: B1 | C11: DMR03181 | D11: APS60135 | E11: {=IFERROR(INDEX(Metadata!M:M, MATCH(C11,Metadata!A:A, 0)),"")} -> SHAM | F11: =IFERROR(INDEX(Metadata!N:N, MATCH(C11,Metadata!A:A, 0)),"") -> GP 2 | G11: =IFERROR(INDEX(Metadata!I:I, MATCH(C11,Metadata!A:A, 0)),"") -> Female | H11: 45909 | I11: 45947 | J11: Downloaded | K11: 1 | L11: {=IFERROR(INDEX(Metadata!O:O, MATCH(C11,Metadata!A:A, 0)),"")} -> D36 | M11: Off-centered | N11: Off-centered to avoid wound of pittag
A12: 95000000811F7641 | B12: B2 | C12: NA | D12: NA | E12: NA | F12: =IFERROR(INDEX(Metadata!N:N, MATCH(C12,Metadata!A:A, 0)),"") | G12: =IFERROR(INDEX(Metadata!I:I, MATCH(C12,Metadata!A:A, 0)),"") | H12: NA | I12: NA | J12: Not used | K12: 1 | L12: NA
A13: 0700000081190F41 | B13: B3 | C13: DMR03155 | D13: APS36033 | E13: {=IFERROR(INDEX(Metadata!M:M, MATCH(C13,Metadata!A:A, 0)),"")} -> SHAM | F13: =IFERROR(INDEX(Metadata!N:N, MATCH(C13,Metadata!A:A, 0)),"") -> GP 2 | G13: =IFERROR(INDEX(Metadata!I:I, MATCH(C13,Metadata!A:A, 0)),"") -> Female | H13: 45909 | I13: 45947 | J13: Downloaded | K13: 1 | L13: {=IFERROR(INDEX(Metadata!O:O, MATCH(C13,Metadata!A:A, 0)),"")} -> D36
A14: D8000000818C4541 | B14: B4 | C14: DMR03185 | D14: APS36103 | E14: {=IFERROR(INDEX(Metadata!M:M, MATCH(C14,Metadata!A:A, 0)),"")} -> Secondary | F14: =IFERROR(INDEX(Metadata!N:N, MATCH(C14,Metadata!A:A, 0)),"") -> GP 1 | G14: =IFERROR(INDEX(Metadata!I:I, MATCH(C14,Metadata!A:A, 0)),"") -> Female | H14: 45902 | I14: 45944 | J14: Downloaded | K14: 1 | L14: {=IFERROR(INDEX(Metadata!O:O, MATCH(C14,Metadata!A:A, 0)),"")} -> D36
A15: 1000000081241041 | B15: B5 | C15: DMR03175 | D15: APS36101 | E15: {=IFERROR(INDEX(Metadata!M:M, MATCH(C15,Metadata!A:A, 0)),"")} -> Secondary | F15: =IFERROR(INDEX(Metadata!N:N, MATCH(C15,Metadata!A:A, 0)),"") -> GP 1 | G15: =IFERROR(INDEX(Metadata!I:I, MATCH(C15,Metadata!A:A, 0)),"") -> Male | H15: 45902 | I15: 45911 | J15: No Data | K15: 1 | L15: {=IFERROR(INDEX(Metadata!O:O, MATCH(C15,Metadata!A:A, 0)),"")} -> D3
A16: E500000081218941 | B16: B6 | C16: DMR03160 | D16: APS60109 | E16: {=IFERROR(INDEX(Metadata!M:M, MATCH(C16,Metadata!A:A, 0)),"")} -> SHAM | F16: =IFERROR(INDEX(Metadata!N:N, MATCH(C16,Metadata!A:A, 0)),"") -> GP 1 | G16: =IFERROR(INDEX(Metadata!I:I, MATCH(C16,Metadata!A:A, 0)),"") -> Female | H16: 45906 | I16: 45909 | J16: Downloaded | K16: 1 | L16: {=IFERROR(INDEX(Metadata!O:O, MATCH(C16,Metadata!A:A, 0)),"")} -> D1
A17: 6100000081222041 | B17: B7 | C17: DMR03195 | D17: APS60081 | E17: {=IFERROR(INDEX(Metadata!M:M, MATCH(C17,Metadata!A:A, 0)),"")} -> NoCo | F17: =IFERROR(INDEX(Metadata!N:N, MATCH(C17,Metadata!A:A, 0)),"") -> GP 1 | G17: =IFERROR(INDEX(Metadata!I:I, MATCH(C17,Metadata!A:A, 0)),"") -> Male | H17: 45906 | I17: 45929 | J17: Downloaded | K17: 1 | L17: {=IFERROR(INDEX(Metadata!O:O, MATCH(C17,Metadata!A:A, 0)),"")} -> D36
A18: 63000000811C2F41 | B18: B8 | C18: DMR03180 | D18: APS60146 | E18: {=IFERROR(INDEX(Metadata!M:M, MATCH(C18,Metadata!A:A, 0)),"")} -> SHAM | F18: =IFERROR(INDEX(Metadata!N:N, MATCH(C18,Metadata!A:A, 0)),"") -> GP 2 | G18: =IFERROR(INDEX(Metadata!I:I, MATCH(C18,Metadata!A:A, 0)),"") -> Male | H18: 45909 | I18: 45947 | J18: Downloaded | K18: 1 | L18: {=IFERROR(INDEX(Metadata!O:O, MATCH(C18,Metadata!A:A, 0)),"")} -> D36
A19: CD00000081881A41 | B19: B9 | C19: DMR03158 | D19: APS36010_boost | E19: {=IFERROR(INDEX(Metadata!M:M, MATCH(C19,Metadata!A:A, 0)),"")} -> Dual | F19: =IFERROR(INDEX(Metadata!N:N, MATCH(C19,Metadata!A:A, 0)),"") -> GP 2 | G19: =IFERROR(INDEX(Metadata!I:I, MATCH(C19,Metadata!A:A, 0)),"") -> Male | H19: 45932 | I19: 45947 | J19: Downloaded | K19: 1 | L19: {=IFERROR(INDEX(Metadata!O:O, MATCH(C19,Metadata!A:A, 0)),"")} -> D36
A20: AC00000081223941 | B20: C1 | C20: DMR03184 | D20: APS60160 | E20: {=IFERROR(INDEX(Metadata!M:M, MATCH(C20,Metadata!A:A, 0)),"")} -> Primary | F20: =IFERROR(INDEX(Metadata!N:N, MATCH(C20,Metadata!A:A, 0)),"") -> GP 1 | G20: =IFERROR(INDEX(Metadata!I:I, MATCH(C20,Metadata!A:A, 0)),"") -> Female | H20: 45902 | I20: 45944 | J20: Downloaded | K20: 1 | L20: {=IFERROR(INDEX(Metadata!O:O, MATCH(C20,Metadata!A:A, 0)),"")} -> D36
A21: BB000000818AFE41 | B21: C2 | C21: DMR03153 | D21: APS60079 | E21: {=IFERROR(INDEX(Metadata!M:M, MATCH(C21,Metadata!A:A, 0)),"")} -> NoCo | F21: =IFERROR(INDEX(Metadata!N:N, MATCH(C21,Metadata!A:A, 0)),"") -> GP 2 | G21: =IFERROR(INDEX(Metadata!I:I, MATCH(C21,Metadata!A:A, 0)),"") -> Male | H21: 45909 | I21: 45932 | J21: Missing | K21: 1 | L21: {=IFERROR(INDEX(Metadata!O:O, MATCH(C21,Metadata!A:A, 0)),"")} -> D36
A22: 0C00000081829341 | B22: C3 | C22: DMR03193 | D22: APS36008 | E22: {=IFERROR(INDEX(Metadata!M:M, MATCH(C22,Metadata!A:A, 0)),"")} -> NoCo | F22: =IFERROR(INDEX(Metadata!N:N, MATCH(C22,Metadata!A:A, 0)),"") -> GP 2 | G22: =IFERROR(INDEX(Metadata!I:I, MATCH(C22,Metadata!A:A, 0)),"") -> Male | H22: 45909 | I22: 45947 | J22: Downloaded | K22: 1 | L22: {=IFERROR(INDEX(Metadata!O:O, MATCH(C22,Metadata!A:A, 0)),"")} -> D36 | M22: Butt | N22: Some bad data points
A23: 9B000000811F0F41 | B23: C4 | C23: DMR03186 | D23: APS36057_boost | E23: {=IFERROR(INDEX(Metadata!M:M, MATCH(C23,Metadata!A:A, 0)),"")} -> Primary | F23: =IFERROR(INDEX(Metadata!N:N, MATCH(C23,Metadata!A:A, 0)),"") -> GP 2 | G23: =IFERROR(INDEX(Metadata!I:I, MATCH(C23,Metadata!A:A, 0)),"") -> Male | H23: 45932 | I23: 45947 | J23: Downloaded | K23: 1 | L23: {=IFERROR(INDEX(Metadata!O:O, MATCH(C23,Metadata!A:A, 0)),"")} -> D36
A24: 1D00000081175641 | B24: C5 | C24: DMR03157 | D24: APS60118 | E24: {=IFERROR(INDEX(Metadata!M:M, MATCH(C24,Metadata!A:A, 0)),"")} -> Primary | F24: =IFERROR(INDEX(Metadata!N:N, MATCH(C24,Metadata!A:A, 0)),"") -> GP 1 | G24: =IFERROR(INDEX(Metadata!I:I, MATCH(C24,Metadata!A:A, 0)),"") -> Male | H24: 45902 | I24: 45944 | J24: Downloaded | K24: 1 | L24: {=IFERROR(INDEX(Metadata!O:O, MATCH(C24,Metadata!A:A, 0)),"")} -> D36
A25: 3C000000811C1941 | B25: C6 | C25: DMR03164 | D25: APS60088 | E25: {=IFERROR(INDEX(Metadata!M:M, MATCH(C25,Metadata!A:A, 0)),"")} -> Primary | F25: =IFERROR(INDEX(Metadata!N:N, MATCH(C25,Metadata!A:A, 0)),"") -> GP 2 | G25: =IFERROR(INDEX(Metadata!I:I, MATCH(C25,Metadata!A:A, 0)),"") -> Female | H25: 45902 | I25: 45932 | J25: No Data | K25: 1 | L25: {=IFERROR(INDEX(Metadata!O:O, MATCH(C25,Metadata!A:A, 0)),"")} -> D36
A26: 19000000811D8A41 | B26: C7 | C26: DMR03151 | D26: APS36011 | E26: {=IFERROR(INDEX(Metadata!M:M, MATCH(C26,Metadata!A:A, 0)),"")} -> Dual | F26: =IFERROR(INDEX(Metadata!N:N, MATCH(C26,Metadata!A:A, 0)),"") -> GP 2 | G26: =IFERROR(INDEX(Metadata!I:I, MATCH(C26,Metadata!A:A, 0)),"") -> Male | H26: 45902 | I26: 45932 | J26: Downloaded | K26: 1 | L26: {=IFERROR(INDEX(Metadata!O:O, MATCH(C26,Metadata!A:A, 0)),"")} -> D21
A27: BD000000811A6E41 | B27: C8 | C27: DMR03173 | D27: APS60086 | E27: {=IFERROR(INDEX(Metadata!M:M, MATCH(C27,Metadata!A:A, 0)),"")} -> Primary | F27: =IFERROR(INDEX(Metadata!N:N, MATCH(C27,Metadata!A:A, 0)),"") -> GP 1 | G27: =IFERROR(INDEX(Metadata!I:I, MATCH(C27,Metadata!A:A, 0)),"") -> Female | H27: 45902 | I27: 45913 | J27: Downloaded | K27: 1 | L27: {=IFERROR(INDEX(Metadata!O:O, MATCH(C27,Metadata!A:A, 0)),"")} -> D5
A28: 7E00000081837A41 | B28: C9 | C28: DMR03170 | D28: APS60073 | E28: {=IFERROR(INDEX(Metadata!M:M, MATCH(C28,Metadata!A:A, 0)),"")} -> NoCo | F28: =IFERROR(INDEX(Metadata!N:N, MATCH(C28,Metadata!A:A, 0)),"") -> GP 1 | G28: =IFERROR(INDEX(Metadata!I:I, MATCH(C28,Metadata!A:A, 0)),"") -> Female | H28: 45906 | I28: 45944 | J28: Downloaded | K28: 1 | L28: {=IFERROR(INDEX(Metadata!O:O, MATCH(C28,Metadata!A:A, 0)),"")} -> D36
A29: 60000000811CB941 | B29: J1 | C29: DMR03177 | D29: APS36050 | E29: {=IFERROR(INDEX(Metadata!M:M, MATCH(C29,Metadata!A:A, 0)),"")} -> Secondary | F29: =IFERROR(INDEX(Metadata!N:N, MATCH(C29,Metadata!A:A, 0)),"") -> GP 2 | G29: =IFERROR(INDEX(Metadata!I:I, MATCH(C29,Metadata!A:A, 0)),"") -> Female | H29: 45902 | I29: 45947 | J29: No Data | K29: 1 | L29: {=IFERROR(INDEX(Metadata!O:O, MATCH(C29,Metadata!A:A, 0)),"")} -> D36
A30: 8C00000081197141 | B30: J2 | C30: DMR03172 | D30: APS60074 | E30: {=IFERROR(INDEX(Metadata!M:M, MATCH(C30,Metadata!A:A, 0)),"")} -> Secondary | F30: =IFERROR(INDEX(Metadata!N:N, MATCH(C30,Metadata!A:A, 0)),"") -> GP 2 | G30: =IFERROR(INDEX(Metadata!I:I, MATCH(C30,Metadata!A:A, 0)),"") -> Female | H30: 45902 | I30: 45947 | J30: Downloaded | K30: 1 | L30: {=IFERROR(INDEX(Metadata!O:O, MATCH(C30,Metadata!A:A, 0)),"")} -> D36
A31: 06000000818A0441 | B31: J3 | C31: DMR03188 | D31: APS36081 | E31: {=IFERROR(INDEX(Metadata!M:M, MATCH(C31,Metadata!A:A, 0)),"")} -> SHAM | F31: =IFERROR(INDEX(Metadata!N:N, MATCH(C31,Metadata!A:A, 0)),"") -> GP 2 | G31: =IFERROR(INDEX(Metadata!I:I, MATCH(C31,Metadata!A:A, 0)),"") -> Male | H31: 45909 | I31: 45934 | J31: Downloaded | K31: 1 | L31: {=IFERROR(INDEX(Metadata!O:O, MATCH(C31,Metadata!A:A, 0)),"")} -> D23
A32: E6000000811F0341 | B32: J4 | C32: DMR03166 | D32: APS60100 | E32: {=IFERROR(INDEX(Metadata!M:M, MATCH(C32,Metadata!A:A, 0)),"")} -> SHAM | F32: =IFERROR(INDEX(Metadata!N:N, MATCH(C32,Metadata!A:A, 0)),"") -> GP 1 | G32: =IFERROR(INDEX(Metadata!I:I, MATCH(C32,Metadata!A:A, 0)),"") -> Female | H32: 45906 | I32: 45909 | J32: Downloaded | K32: 1 | L32: {=IFERROR(INDEX(Metadata!O:O, MATCH(C32,Metadata!A:A, 0)),"")} -> D1
A33: 1200000081836B41 | B33: J5 | C33: DMR03168 | D33: APS60115 | E33: {=IFERROR(INDEX(Metadata!M:M, MATCH(C33,Metadata!A:A, 0)),"")} -> Secondary | F33: =IFERROR(INDEX(Metadata!N:N, MATCH(C33,Metadata!A:A, 0)),"") -> GP 1 | G33: =IFERROR(INDEX(Metadata!I:I, MATCH(C33,Metadata!A:A, 0)),"") -> Female | H33: 45902 | I33: 45929 | J33: Downloaded | K33: 1 | L33: {=IFERROR(INDEX(Metadata!O:O, MATCH(C33,Metadata!A:A, 0)),"")} -> D36
A34: 1C000000811B7F41 | B34: J6 | C34: DMR03192 | D34: APS60113_boost | E34: {=IFERROR(INDEX(Metadata!M:M, MATCH(C34,Metadata!A:A, 0)),"")} -> SHAM | F34: =IFERROR(INDEX(Metadata!N:N, MATCH(C34,Metadata!A:A, 0)),"") -> GP 2 | G34: =IFERROR(INDEX(Metadata!I:I, MATCH(C34,Metadata!A:A, 0)),"") -> Male | H34: 45932 | I34: 45947 | J34: Downloaded | K34: 1 | L34: {=IFERROR(INDEX(Metadata!O:O, MATCH(C34,Metadata!A:A, 0)),"")} -> D36
A35: B00000008121E041 | B35: J7 | C35: DMR03192 | D35: APS60113 | E35: {=IFERROR(INDEX(Metadata!M:M, MATCH(C35,Metadata!A:A, 0)),"")} -> SHAM | F35: =IFERROR(INDEX(Metadata!N:N, MATCH(C35,Metadata!A:A, 0)),"") -> GP 2 | G35: =IFERROR(INDEX(Metadata!I:I, MATCH(C35,Metadata!A:A, 0)),"") -> Male | H35: 45909 | I35: 45932 | J35: Downloaded | K35: 1 | L35: {=IFERROR(INDEX(Metadata!O:O, MATCH(C35,Metadata!A:A, 0)),"")} -> D36 | M35: Butt
A36: 7E00000081224441 | B36: J8 | C36: DMR03156 | D36: APS60111 | E36: {=IFERROR(INDEX(Metadata!M:M, MATCH(C36,Metadata!A:A, 0)),"")} -> SHAM | F36: =IFERROR(INDEX(Metadata!N:N, MATCH(C36,Metadata!A:A, 0)),"") -> GP 2 | G36: =IFERROR(INDEX(Metadata!I:I, MATCH(C36,Metadata!A:A, 0)),"") -> Female | H36: 45909 | I36: 45947 | J36: Downloaded | K36: 1 | L36: {=IFERROR(INDEX(Metadata!O:O, MATCH(C36,Metadata!A:A, 0)),"")} -> D36
A37: 8D000000818A7A41 | B37: J9 | C37: DMR03163 | D37: APS60156 | E37: {=IFERROR(INDEX(Metadata!M:M, MATCH(C37,Metadata!A:A, 0)),"")} -> Secondary | F37: =IFERROR(INDEX(Metadata!N:N, MATCH(C37,Metadata!A:A, 0)),"") -> GP 2 | G37: =IFERROR(INDEX(Metadata!I:I, MATCH(C37,Metadata!A:A, 0)),"") -> Female | H37: 45902 | I37: 45932 | J37: Missing | K37: 1 | L37: {=IFERROR(INDEX(Metadata!O:O, MATCH(C37,Metadata!A:A, 0)),"")} -> D36
A38: 2B0000008189E941 | B38: K1 | C38: DMR03171 | D38: APS60134 | E38: {=IFERROR(INDEX(Metadata!M:M, MATCH(C38,Metadata!A:A, 0)),"")} -> Dual | F38: =IFERROR(INDEX(Metadata!N:N, MATCH(C38,Metadata!A:A, 0)),"") -> GP 1 | G38: =IFERROR(INDEX(Metadata!I:I, MATCH(C38,Metadata!A:A, 0)),"") -> Female | H38: 45902 | I38: 45912 | J38: Downloaded | K38: 1 | L38: {=IFERROR(INDEX(Metadata!O:O, MATCH(C38,Metadata!A:A, 0)),"")} -> D4
A39: 01000000811F6C41 | B39: K2 | C39: DMR03176 | D39: APS60082 | E39: {=IFERROR(INDEX(Metadata!M:M, MATCH(C39,Metadata!A:A, 0)),"")} -> Primary | F39: =IFERROR(INDEX(Metadata!N:N, MATCH(C39,Metadata!A:A, 0)),"") -> GP 1 | G39: =IFERROR(INDEX(Metadata!I:I, MATCH(C39,Metadata!A:A, 0)),"") -> Female | H39: 45902 | I39: 45944 | J39: No Data | K39: 1 | L39: {=IFERROR(INDEX(Metadata!O:O, MATCH(C39,Metadata!A:A, 0)),"")} -> D36
A40: 7D0000008122D241 | B40: K3 | C40: DMR03189 | D40: APS60112 | E40: {=IFERROR(INDEX(Metadata!M:M, MATCH(C40,Metadata!A:A, 0)),"")} -> Secondary | F40: =IFERROR(INDEX(Metadata!N:N, MATCH(C40,Metadata!A:A, 0)),"") -> GP 1 | G40: =IFERROR(INDEX(Metadata!I:I, MATCH(C40,Metadata!A:A, 0)),"") -> Male | H40: 45902 | I40: 45913 | J40: Downloaded | K40: 1 | L40: {=IFERROR(INDEX(Metadata!O:O, MATCH(C40,Metadata!A:A, 0)),"")} -> D5
...

Sheet Pivot Table 2
A1: BUTT Status | B1: (Multiple Items)
A2: Experiment D Died | B2: D3
A4: COUNTA of BUTT Status | B4: Date Attached
A5: Treatment | B5: 45906 | C5: Grand Total
A6: NoCo | B6: 1 | C6: 1
A7: Grand Total | B7: 1 | C7: 1

Sheet Metadata
A1: Band # | B1: Pittag # | C1: Capture Date | D1: Capture Site | E1: FA length | F1: Inital Weight | G1: weights for group assignment | H1: BMI | I1: Sex | J1: Rep Condition | K1: Status on 5-Sep, 2025 | L1: group assignment data | M1: TREATMENT | N1: Group | O1: Date Died | P1: Notes
A2: DMR03151 | B2: APS36011 | C2: 45873 | D2: Scott's House | E2: 41.77 | F2: 10.8 | G2: 12.5 | H2: 0.29925784 | I2: Male | K2: Self feeding | L2: DMR03151 - BMI: 0.299258 (Male) | M2: Dual | N2: GP 2 | O2: D21 | Q2: 2-Oct: Put down
A3: DMR03152 | B3: APS36021 | C3: 45873 | D3: Scott's House | E3: 42.72 | F3: 11.5 | G3: 22.7 | H3: 0.53136704 | I3: Male | K3: Self feeding | L3: DMR03152 - BMI: 0.531367 (Male) | M3: Primary | N3: GP 2 | O3: D36
A4: DMR03153 | B4: APS60079 | C4: 45873 | D4: Scott's House | E4: 45.12 | F4: 11.8 | G4: 21.5 | H4: 0.47650709 | I4: Male | K4: Self feeding | L4: DMR03153 - BMI: 0.476507 (Male) | M4: NoCo | N4: GP 2 | O4: D36
A5: DMR03154 | B5: APS60123 | C5: 45873 | D5: Scott's House | E5: 42.81 | F5: 13.3 | G5: 23.8 | H5: 0.55594487 | I5: Male | K5: Self feeding | L5: DMR03154 - BMI: 0.555945 (Male) | M5: SHAM | N5: GP 1 | O5: D36
A6: DMR03155 | B6: APS36033 | C6: 45875 | D6: Warriors Mark Farmhouse | E6: 45.16 | F6: 14.6 | G6: 26.5 | H6: 0.58680248 | I6: Female | K6: Self feeding | L6: DMR03155 - BMI: 0.586802 (Female) | M6: SHAM | N6: GP 2 | O6: D36
A7: DMR03156 | B7: APS60111 | C7: 45875 | D7: Warriors Mark Farmhouse | E7: 46.38 | F7: 13.3 | G7: 24.8 | H7: 0.53471324 | I7: Female | K7: Self feeding | L7: DMR03156 - BMI: 0.534713 (Female) | M7: SHAM | N7: GP 2 | O7: D36
A8: DMR03157 | B8: APS60118 | C8: 45875 | D8: Warriors Mark Farmhouse | E8: 45.11 | F8: 12.8 | G8: 24.6 | H8: 0.54533363 | I8: Male | K8: Self feeding | L8: DMR03157 - BMI: 0.545334 (Male) | M8: Primary | N8: GP 1 | O8: D36
A9: DMR03158 | B9: APS36010 | C9: 45875 | D9: Warriors Mark Farmhouse | E9: 42.79 | F9: 11.5 | G9: 15.3 | H9: 0.35756018 | I9: Male | K9: Self feeding | L9: DMR03158 - BMI: 0.357560 (Male) | M9: Dual | N9: GP 2 | O9: D36 | Q9: 5-Sep: Noticed infection at pittag injection site on 5-Sep. Isolating in infection cage. 6-Sep: Wound is bad but no pus just bleeding. Starting to scab over. Still very active. Fed a few mealworms
A10: DMR03159 | B10: APS36007 | C10: 45875 | D10: Warriors Mark Farmhouse | E10: 44.94 | F10: 13.6 | G10: 22.8 | H10: 0.50734312 | I10: Female | K10: Self feeding | L10: DMR03159 - BMI: 0.507343 (Female) | M10: Dual | N10: GP 2 | O10: D36
A11: DMR03160 | B11: APS60109 | C11: 45875 | D11: Warriors Mark Farmhouse | E11: 44.48 | F11: 14.4 | G11: 21.5 | H11: 0.48336331 | I11: Female | K11: Deceased | L11: DMR03160 - BMI: 0.483363 (Female) | M11: SHAM | N11: GP 1 | O11: D1 | P11: Replaced with DMR03188 | Q11: Huge hole in wing where band was. Broken wing. Euthanized 9-Sep
A12: DMR03161 | B12: APS60125 | C12: 45875 | D12: Warriors Mark Farmhouse | E12: 46.58 | F12: 17.5 | G12: 33.4 | H12: 0.71704594 | I12: Female | K12: Self feeding | L12: DMR03161 - BMI: 0.717046 (Female) | M12: Secondary | N12: GP 2 | O12: D27 | P12: 8-Oct: Found dead by animal care team. 4-Oct: Cold and lethargic
A13: DMR03162 | B13: APS36106 | C13: 45875 | D13: Warriors Mark Farmhouse | E13: 45.26 | F13: 10.9 | G13: 24.3 | H13: 0.53689792 | I13: Female | K13: Self feeding | L13: DMR03162 - BMI: 0.536898 (Female) | M13: Dual | N13: GP 1 | O13: D36
A14: DMR03163 | B14: APS60156 | C14: 45875 | D14: Warriors Mark Farmhouse | E14: 48.47 | F14: 18.6 | G14: 22 | H14: 0.453889 | I14: Female | K14: Self feeding | L14: DMR03163 - BMI: 0.453889 (Female) | M14: Secondary | N14: GP 2 | O14: D36
A15: DMR03164 | B15: APS60088 | C15: 45875 | D15: Warriors Mark Farmhouse | E15: 45.49 | F15: 13.9 | G15: 26 | H15: 0.57155419 | I15: Female | K15: Self feeding | L15: DMR03164 - BMI: 0.571554 (Female) | M15: Primary | N15: GP 2 | O15: D36
A16: DMR03165 | B16: APS60087 | C16: 45875 | D16: Warriors Mark Farmhouse | E16: 45.83 | F16: 15.1 | G16: 34.5 | H16: 0.75278202 | I16: Female | K16: Deceased | L16: DMR03165 - BMI: 0.752782 (Female) | M16: NoCo | N16: GP 2 | O16: D5 | Q16: 16-Sep: Found dead by animal care staff. Stomach feels a bit squishy. Coat not very clean. Notes that he was a bleeder on 12-Sep and that right thumb looked swollen. Not holding on to cage with right thumb having a hard time moving around. Seen at the bottom of flight cage on 14-Sep but reactive when handled and put back.
A17: DMR03166 | B17: APS60100 | C17: 45875 | D17: Warriors Mark Farmhouse | E17: 47.63 | F17: 17.4 | G17: 36 | H17: 0.75582616 | I17: Female | K17: Deceased | L17: DMR03166 - BMI: 0.755826 (Female) | M17: SHAM | N17: GP 1 | O17: D1 | P17: Replaced with DMR03180 | Q17: Bit Ashlyn. Euthanized 9-Sep and sent in for rabies testing
A18: DMR03168 | B18: APS60115 | C18: 45875 | D18: Warriors Mark Farmhouse | E18: 46.37 | F18: 15.6 | G18: 26.5 | H18: 0.57149019 | I18: Female | K18: Self feeding | L18: DMR03168 - BMI: 0.571490 (Female) | M18: Secondary | N18: GP 1 | O18: D36 | Q18: 6-Sep: Back is bleeding and a bit of pus coming from under the iButton. Lifted the iButton a bit and cleaned the whole back with alcohol wipe. Put in quarantine cage to keep an eye on
A19: DMR03169 | B19: APS60140 | C19: 45875 | D19: Warriors Mark Farmhouse | E19: 44.82 | F19: 12.2 | G19: 24.7 | H19: 0.55109326 | I19: Female | K19: Deceased | L19: DMR03169 - BMI: 0.551093 (Female) | M19: NoCo | N19: GP 2 | O19: D-4 | P19: Replaced with DMR03193 | Q19: Looked really bad on morning of 4-Sep. By late afternoon looking worse and lethargic. Bat looked very yellow and squishy. Put down using ISO
A20: DMR03170 | B20: APS60073 | C20: 45875 | D20: Warriors Mark Farmhouse | E20: 47.09 | F20: 15.9 | G20: 27.5 | H20: 0.58398811 | I20: Female | K20: Self feeding | L20: DMR03170 - BMI: 0.583988 (Female) | M20: NoCo | N20: GP 1 | O20: D36
A21: DMR03171 | B21: APS60134 | C21: 45875 | D21: Warriors Mark Farmhouse | E21: 46.54 | F21: 13.8 | G21: 30.1 | H21: 0.64675548 | I21: Female | K21: Deceased | L21: DMR03171 - BMI: 0.646755 (Female) | M21: Dual | N21: GP 1 | O21: D4 | Q21: 5-Sep: Noticed infection at pittag injection site on 5-Sep. Isolating in infection cage. Yellowing color and squishy like 169, but still very active. 6-Sep: Still very active, looks pretty good. Did not notice any bleeding or oozing on back. Yellowish color has gone away. Kept in quarantine cage to keep an eye on. Found dead on Sep 12. Looked healthy and fine.
A22: DMR03172 | B22: APS60074 | C22: 45875 | D22: Warriors Mark Farmhouse | E22: 47.34 | F22: 14.6 | G22: 25.5 | H22: 0.53865653 | I22: Female | K22: Self feeding | L22: DMR03172 - BMI: 0.538657 (Female) | M22: Secondary | N22: GP 2 | O22: D36
A23: DMR03173 | B23: APS60086 | C23: 45875 | D23: Warriors Mark Farmhouse | E23: 46.23 | F23: 16.6 | G23: 33.5 | H23: 0.72463768 | I23: Female | K23: Deceased | L23: DMR03173 - BMI: 0.724638 (Female) | M23: Primary | N23: GP 1 | O23: D5 | Q23: 13-Sep: Extremely weak and lethargic. Put down.
A24: DMR03174 | B24: APS60148 | C24: 45875 | D24: Warriors Mark Farmhouse | E24: 47.71 | F24: 15.4 | G24: 25.5 | H24: 0.53447914 | I24: Female | K24: Deceased | L24: DMR03174 - BMI: 0.534479 (Female) | M24: NoCo | N24: GP 1 | O24: D6 | Q24: 14-Sep: Found dead in the morning. Looks healthy and in good condition.
A25: DMR03175 | B25: APS36101 | C25: 45875 | D25: Warriors Mark Farmhouse | E25: 44.49 | F25: 11.8 | G25: 23.3 | H25: 0.52371319 | I25: Male | K25: Deceased | L25: DMR03175 - BMI: 0.523713 (Male) | M25: Secondary | N25: GP 1 | O25: D3 | P25: Replaced with DMR03194 | Q25: Found dead around noon on Sep 11th. Body still warm and in good condition. No visible wounds or infections. Unable to collect blood samples on Sep 10th - could be related to death.
A26: DMR03176 | B26: APS60082 | C26: 45881 | D26: Troxelville House | E26: 41.85 | F26: 15.2 | G26: 19.7 | H26: 0.47072879 | I26: Female | K26: Self feeding | L26: DMR03176 - BMI: 0.470729 (Female) | M26: Primary | N26: GP 1 | O26: D36
A27: DMR03177 | B27: APS36050 | C27: 45884 | D27: Scott's House | E27: 41.17 | F27: 15.5 | G27: 13.7 | H27: 0.33276658 | I27: Female | K27: Self feeding | L27: DMR03177 - BMI: 0.332767 (Female) | M27: Secondary | N27: GP 2 | O27: D36
A28: DMR03178 | B28: APS60141 | C28: 45884 | D28: Scott's House | E28: 46.4 | F28: 18.6 | G28: 15.9 | H28: 0.34267241 | I28: Female | K28: Self feeding | L28: DMR03178 - BMI: 0.342672 (Female) | M28: NoCo | N28: GP 2 | O28: D36
A29: DMR03179 | B29: APS60065 | C29: 45884 | D29: Scott's House | E29: 43.29 | F29: 13.1 | G29: 15.1 | H29: 0.34881035 | I29: Female | K29: Deceased | L29: DMR03179 - BMI: 0.348810 (Female) | M29: SHAM | N29: GP 1 | O29: D5 | Q29: 12-Sep: Only half holding on to cage wall. Reacted when grabbing him by opening mouth wide but not trying to move around at all. When placed on back not trying to flip itself back over. In good condition overall. Placed him back on the wall and he stayed in the same spot right side up.13-Sep: Found dead.
A30: DMR03180 | B30: APS60146 | C30: 45884 | D30: Scott's House | E30: 45.32 | F30: 15.2 | G30: 22 | H30: 0.48543689 | I30: Male | K30: Self feeding | L30: DMR03180 - BMI: 0.4854368932 (Male) | M30: SHAM | N30: GP 2 | O30: D36 | P30: Was spare but replaced DMR03166
A31: DMR03181 | B31: APS60135 | C31: 45887 | D31: Old Danville Highway Barn | E31: 46.65 | F31: 18.2 | G31: 14.8 | H31: 0.31725616 | I31: Female | K31: Self feeding | L31: DMR03181 - BMI: 0.317256 (Female) | M31: SHAM | N31: GP 2 | O31: D36
A32: DMR03182 | B32: APS60132 | C32: 45887 | D32: Old Danville Highway Barn | E32: 45.2 | F32: 16.7 | G32: 20.1 | H32: 0.44469027 | I32: Female | K32: Self feeding | L32: DMR03182 - BMI: 0.444690 (Female) | M32: Dual | N32: GP 1 | O32: D36
A33: DMR03183 | B33: APS36026 | C33: 45887 | D33: Old Danville Highway Barn | E33: 46.95 | F33: 15.9 | G33: 20.1 | H33: 0.42811502 | I33: Female | K33: Self feeding | L33: DMR03183 - BMI: 0.428115 (Female) | M33: Primary | N33: GP 2 | O33: D36
A34: DMR03184 | B34: APS60160 | C34: 45887 | D34: Old Danville Highway Barn | E34: 47.82 | F34: 20.1 | G34: 16.2 | H34: 0.33877039 | I34: Female | K34: Self feeding | L34: DMR03184 - BMI: 0.338770 (Female) | M34: Primary | N34: GP 1 | O34: D36
A35: DMR03185 | B35: APS36103 | C35: 45887 | D35: Old Danville Highway Barn | E35: 44.86 | F35: 16.2 | G35: 14 | H35: 0.31208203 | I35: Female | K35: Self feeding | L35: DMR03185 - BMI: 0.312082 (Female) | M35: Secondary | N35: GP 1 | O35: D36
A36: DMR03186 | B36: APS36057 | C36: 45887 | D36: Old Danville Highway Barn | E36: 44.33 | F36: 17.3 | G36: 14 | H36: 0.31581322 | I36: Male | K36: Self feeding | L36: DMR03186 - BMI: 0.315813 (Male) | M36: Primary | N36: GP 2 | O36: D36
A37: DMR03187 | B37: APS36036 | C37: 45887 | D37: Old Danville Highway Barn | E37: 46.92 | F37: 16.1 | G37: 15 | H37: 0.31969309 | I37: Female | K37: Self feeding | L37: DMR03187 - BMI: 0.319693 (Female) | M37: Dual | N37: GP 1 | O37: D36
A38: DMR03188 | B38: APS36081 | C38: 45887 | D38: Old Danville Highway Barn | E38: 44.5 | F38: 14.5 | G38: 22.3 | H38: 0.5011236 | I38: Male | K38: Self feeding | L38: DMR03188 - BMI: 0.5011235955 (Male) | M38: SHAM | N38: GP 2 | O38: D23 | P38: Was spare but replaced DMR03160 | Q38: 10/3: Maybe wrist is dislocated. Very bruised and swollen; 10/4: found dead
A39: DMR03189 | B39: APS60112 | C39: 45888 | D39: Old Danville Highway Barn | E39: 44.75 | F39: 14.7 | G39: 17.2 | H39: 0.38435754 | I39: Male | K39: Deceased | L39: DMR03189 - BMI: 0.384358 (Male) | M39: Secondary | N39: GP 1 | O39: D5 | Q39: 13-Sep: Found dead.
A40: DMR03190 | B40: APS36067 | C40: 45888 | D40: Old Danville Highway Barn | E40: 45.57 | F40: 15 | G40: 14.4 | H40: 0.31599737 | I40: Male | K40: Deceased | L40: DMR03190 - BMI: 0.315997 (Male) | M40: NoCo | N40: GP 1 | O40: D3 | Q40: Has been aggressive and biting since Sep 7th. When returning to flight cages would approach other bats and bite them. Around 1200 on Sep 11 was found with bite injury to face and bloody eye, but still active. Found on floor of flight cage around 1700 on Sep 11th, very weak, cold, and half swollen face. Put down with isoflurane
...
